Workbook

Sheet Inputs
A1: Years of Plenty, Years of Bread
A2: Retirement projection. All values in 2026 dollars (real terms, net of inflation).
A3: Blue cells are inputs you can change. Black are formulas. Green are cross-sheet links.
A4: PERSONAL
A5: Current age | B5: 29 | C5: yrs
A6: Net worth today | B6: 400000 | C6: CAD
A7: Career start age | B7: 22 | C7: yrs | D7: When CPP contributions began
A8: Lifespan to plan for | B8: 95 | C8: yrs | D8: End-of-plan age
A10: CAREER AND SAVING
A11: Income now | B11: 190000 | C11: CAD/yr
A12: Peak income | B12: 215000 | C12: CAD/yr
A13: Years until peak | B13: 5 | C13: yrs
A14: Years held at peak | B14: 5 | C14: yrs
A15: Income after step-down | B15: 130000 | C15: CAD/yr
A16: Saving rate | B16: 0.28 | C16: of after-tax
A18: MARKETS AND RETIREMENT
A19: Real return (after inflation) | B19: 0.07 | C19: per year | D19: Stocks ~7%, balanced ~5%
A20: Retirement age | B20: 60 | C20: yrs | D20: Age you stop working
A22: GOVERNMENT BENEFITS
A23: CPP claim age | B23: 70 | C23: yrs | D23: 60 to 70. Defer to 70 boosts by 42%.
A24: CPP at 65, max contributor | B24: 22000 | C24: CAD/yr | D24: Enhanced CPP, 39+ years of max contributions.
A25: OAS at 65 | B25: 9000 | C25: CAD/yr
A26: OAS clawback threshold | B26: 93000 | C26: CAD/yr | D26: Net taxable income above this triggers clawback.
A28: DERIVED VALUES (FORMULAS, DO NOT EDIT)
A29: Working years (CPP contributions) | B29: =B20-B7 -> 38 | C29: yrs
A30: CPP contribution factor | B30: =MIN(1, B29/39) -> 0.97435897 | C30: of max | D30: 39 contribution years gets you the max.
A31: CPP claim age factor | B31: =IF(B23<65, MAX(0.5, 1-(65-B23)*0.072), MIN(1.42, 1+(B23-65)*0.084)) -> 1.42 | D31: 0.64 at 60, 1.0 at 65, 1.42 at 70.
A32: CPP annual at claim | B32: =B24*B30*B31 -> 30438.974 | C32: CAD/yr
A33: OAS effective claim age | B33: =MAX(65, MIN(70, B20)) -> 65 | C33: yrs | D33: OAS earliest at 65; defer up to 70.
A34: OAS deferral factor | B34: =1+MAX(0,B33-65)*0.072 -> 1 | D34: 1.36 at age 70.
A35: OAS annual at claim | B35: =B25*B34 -> 9000 | C35: CAD/yr
A37: ONTARIO 2026 COMBINED TAX BRACKETS (FEDERAL + PROVINCIAL)
A38: From (CAD) | B38: Marginal rate above | C38: Cumulative tax at threshold
A39: 0 | B39: 0 | C39: 0
A40: 15000 | B40: 0.2005 | C40: =C39+B39*(A40-A39) -> 0
A41: 53359 | B41: 0.2965 | C41: =C40+B40*(A41-A40) -> 7690.9795
A42: 90599 | B42: 0.3148 | C42: =C41+B41*(A42-A41) -> 18732.64
A43: 106717 | B43: 0.3389 | C43: =C42+B42*(A43-A42) -> 23806.586
A44: 111733 | B44: 0.3791 | C44: =C43+B43*(A44-A43) -> 25506.508
A45: 150000 | B45: 0.4341 | C45: =C44+B44*(A45-A44) -> 40013.528
...

Sheet Projection
A1: Age | B1: Phase | C1: Gross income | D1: Tax | E1: After-tax | F1: Saving | G1: Portfolio start | H1: Growth | I1: Contribution | J1: CPP | K1: OAS | L1: Portfolio draw | M1: Total income | N1: Portfolio end
A2: =Inputs!$B$5 -> 29 | B2: =IF(A2<Inputs!$B$20,"work",IF(A2<Inputs!$B$8,"retire","—")) -> work | C2: =IF(B2<>"work",0,IF(A2-Inputs!$B$5<Inputs!$B$13,Inputs!$B$11+(Inputs!$B$12-Inputs!$B$11)*(A2-Inputs!$B$5)/Inputs!$B$13,IF(A2-Inputs!$B$5<Inputs!$B$13+Inputs!$B$14,Inputs!$B$12,Inputs!$B$15))) -> 190000 | D2: =IF(C2<=0,0,VLOOKUP(C2,Inputs!$A$39:$C$48,3,TRUE())+(C2-VLOOKUP(C2,Inputs!$A$39:$C$48,1,TRUE()))*VLOOKUP(C2,Inputs!$A$39:$C$48,2,TRUE())) -> 57639.53 | E2: =C2-D2 -> 132360.47 | F2: =IF(B2="work",E2*Inputs!$B$16,0) -> 37060.932 | G2: =Inputs!$B$6 -> 400000 | H2: =IF(A2>Inputs!$B$8,0,G2*Inputs!$B$19) -> 28000 | I2: =IF(B2="work",F2,0) -> 37060.932 | J2: =IF(AND(A2>=Inputs!$B$23,A2<Inputs!$B$8),Inputs!$B$32,0) -> 0 | K2: =IF(AND(A2>=Inputs!$B$33,A2<Inputs!$B$8),Inputs!$B$35,0) -> 0 | L2: =IF(B2="retire",Summary!$B$11-J2-K2,0) -> 0 | M2: =IF(B2="work",E2,IF(B2="retire",J2+K2+L2,0)) -> 132360.47 | N2: =IF(A2>=Inputs!$B$8,0,G2*(1+Inputs!$B$19)+I2-L2) -> 465060.93
A3: =A2+1 -> 30 | B3: =IF(A3<Inputs!$B$20,"work",IF(A3<Inputs!$B$8,"retire","—")) -> work | C3: =IF(B3<>"work",0,IF(A3-Inputs!$B$5<Inputs!$B$13,Inputs!$B$11+(Inputs!$B$12-Inputs!$B$11)*(A3-Inputs!$B$5)/Inputs!$B$13,IF(A3-Inputs!$B$5<Inputs!$B$13+Inputs!$B$14,Inputs!$B$12,Inputs!$B$15))) -> 195000 | D3: =IF(C3<=0,0,VLOOKUP(C3,Inputs!$A$39:$C$48,3,TRUE())+(C3-VLOOKUP(C3,Inputs!$A$39:$C$48,1,TRUE()))*VLOOKUP(C3,Inputs!$A$39:$C$48,2,TRUE())) -> 59888.03 | E3: =C3-D3 -> 135111.97 | F3: =IF(B3="work",E3*Inputs!$B$16,0) -> 37831.352 | G3: =N2 -> 465060.93 | H3: =IF(A3>Inputs!$B$8,0,G3*Inputs!$B$19) -> 32554.265 | I3: =IF(B3="work",F3,0) -> 37831.352 | J3: =IF(AND(A3>=Inputs!$B$23,A3<Inputs!$B$8),Inputs!$B$32,0) -> 0 | K3: =IF(AND(A3>=Inputs!$B$33,A3<Inputs!$B$8),Inputs!$B$35,0) -> 0 | L3: =IF(B3="retire",Summary!$B$11-J3-K3,0) -> 0 | M3: =IF(B3="work",E3,IF(B3="retire",J3+K3+L3,0)) -> 135111.97 | N3: =IF(A3>=Inputs!$B$8,0,G3*(1+Inputs!$B$19)+I3-L3) -> 535446.55
A4: =A3+1 -> 31 | B4: =IF(A4<Inputs!$B$20,"work",IF(A4<Inputs!$B$8,"retire","—")) -> work | C4: =IF(B4<>"work",0,IF(A4-Inputs!$B$5<Inputs!$B$13,Inputs!$B$11+(Inputs!$B$12-Inputs!$B$11)*(A4-Inputs!$B$5)/Inputs!$B$13,IF(A4-Inputs!$B$5<Inputs!$B$13+Inputs!$B$14,Inputs!$B$12,Inputs!$B$15))) -> 200000 | D4: =IF(C4<=0,0,VLOOKUP(C4,Inputs!$A$39:$C$48,3,TRUE())+(C4-VLOOKUP(C4,Inputs!$A$39:$C$48,1,TRUE()))*VLOOKUP(C4,Inputs!$A$39:$C$48,2,TRUE())) -> 62136.53 | E4: =C4-D4 -> 137863.47 | F4: =IF(B4="work",E4*Inputs!$B$16,0) -> 38601.772 | G4: =N3 -> 535446.55 | H4: =IF(A4>Inputs!$B$8,0,G4*Inputs!$B$19) -> 37481.258 | I4: =IF(B4="work",F4,0) -> 38601.772 | J4: =IF(AND(A4>=Inputs!$B$23,A4<Inputs!$B$8),Inputs!$B$32,0) -> 0 | K4: =IF(AND(A4>=Inputs!$B$33,A4<Inputs!$B$8),Inputs!$B$35,0) -> 0 | L4: =IF(B4="retire",Summary!$B$11-J4-K4,0) -> 0 | M4: =IF(B4="work",E4,IF(B4="retire",J4+K4+L4,0)) -> 137863.47 | N4: =IF(A4>=Inputs!$B$8,0,G4*(1+Inputs!$B$19)+I4-L4) -> 611529.58
A5: =A4+1 -> 32 | B5: =IF(A5<Inputs!$B$20,"work",IF(A5<Inputs!$B$8,"retire","—")) -> work | C5: =IF(B5<>"work",0,IF(A5-Inputs!$B$5<Inputs!$B$13,Inputs!$B$11+(Inputs!$B$12-Inputs!$B$11)*(A5-Inputs!$B$5)/Inputs!$B$13,IF(A5-Inputs!$B$5<Inputs!$B$13+Inputs!$B$14,Inputs!$B$12,Inputs!$B$15))) -> 205000 | D5: =IF(C5<=0,0,VLOOKUP(C5,Inputs!$A$39:$C$48,3,TRUE())+(C5-VLOOKUP(C5,Inputs!$A$39:$C$48,1,TRUE()))*VLOOKUP(C5,Inputs!$A$39:$C$48,2,TRUE())) -> 64385.03 | E5: =C5-D5 -> 140614.97 | F5: =IF(B5="work",E5*Inputs!$B$16,0) -> 39372.192 | G5: =N4 -> 611529.58 | H5: =IF(A5>Inputs!$B$8,0,G5*Inputs!$B$19) -> 42807.07 | I5: =IF(B5="work",F5,0) -> 39372.192 | J5: =IF(AND(A5>=Inputs!$B$23,A5<Inputs!$B$8),Inputs!$B$32,0) -> 0 | K5: =IF(AND(A5>=Inputs!$B$33,A5<Inputs!$B$8),Inputs!$B$35,0) -> 0 | L5: =IF(B5="retire",Summary!$B$11-J5-K5,0) -> 0 | M5: =IF(B5="work",E5,IF(B5="retire",J5+K5+L5,0)) -> 140614.97 | N5: =IF(A5>=Inputs!$B$8,0,G5*(1+Inputs!$B$19)+I5-L5) -> 693708.84
A6: =A5+1 -> 33 | B6: =IF(A6<Inputs!$B$20,"work",IF(A6<Inputs!$B$8,"retire","—")) -> work | C6: =IF(B6<>"work",0,IF(A6-Inputs!$B$5<Inputs!$B$13,Inputs!$B$11+(Inputs!$B$12-Inputs!$B$11)*(A6-Inputs!$B$5)/Inputs!$B$13,IF(A6-Inputs!$B$5<Inputs!$B$13+Inputs!$B$14,Inputs!$B$12,Inputs!$B$15))) -> 210000 | D6: =IF(C6<=0,0,VLOOKUP(C6,Inputs!$A$39:$C$48,3,TRUE())+(C6-VLOOKUP(C6,Inputs!$A$39:$C$48,1,TRUE()))*VLOOKUP(C6,Inputs!$A$39:$C$48,2,TRUE())) -> 66633.53 | E6: =C6-D6 -> 143366.47 | F6: =IF(B6="work",E6*Inputs!$B$16,0) -> 40142.612 | G6: =N5 -> 693708.84 | H6: =IF(A6>Inputs!$B$8,0,G6*Inputs!$B$19) -> 48559.619 | I6: =IF(B6="work",F6,0) -> 40142.612 | J6: =IF(AND(A6>=Inputs!$B$23,A6<Inputs!$B$8),Inputs!$B$32,0) -> 0 | K6: =IF(AND(A6>=Inputs!$B$33,A6<Inputs!$B$8),Inputs!$B$35,0) -> 0 | L6: =IF(B6="retire",Summary!$B$11-J6-K6,0) -> 0 | M6: =IF(B6="work",E6,IF(B6="retire",J6+K6+L6,0)) -> 143366.47 | N6: =IF(A6>=Inputs!$B$8,0,G6*(1+Inputs!$B$19)+I6-L6) -> 782411.07
A7: =A6+1 -> 34 | B7: =IF(A7<Inputs!$B$20,"work",IF(A7<Inputs!$B$8,"retire","—")) -> work | C7: =IF(B7<>"work",0,IF(A7-Inputs!$B$5<Inputs!$B$13,Inputs!$B$11+(Inputs!$B$12-Inputs!$B$11)*(A7-Inputs!$B$5)/Inputs!$B$13,IF(A7-Inputs!$B$5<Inputs!$B$13+Inputs!$B$14,Inputs!$B$12,Inputs!$B$15))) -> 215000 | D7: =IF(C7<=0,0,VLOOKUP(C7,Inputs!$A$39:$C$48,3,TRUE())+(C7-VLOOKUP(C7,Inputs!$A$39:$C$48,1,TRUE()))*VLOOKUP(C7,Inputs!$A$39:$C$48,2,TRUE())) -> 68882.03 | E7: =C7-D7 -> 146117.97 | F7: =IF(B7="work",E7*Inputs!$B$16,0) -> 40913.032 | G7: =N6 -> 782411.07 | H7: =IF(A7>Inputs!$B$8,0,G7*Inputs!$B$19) -> 54768.775 | I7: =IF(B7="work",F7,0) -> 40913.032 | J7: =IF(AND(A7>=Inputs!$B$23,A7<Inputs!$B$8),Inputs!$B$32,0) -> 0 | K7: =IF(AND(A7>=Inputs!$B$33,A7<Inputs!$B$8),Inputs!$B$35,0) -> 0 | L7: =IF(B7="retire",Summary!$B$11-J7-K7,0) -> 0 | M7: =IF(B7="work",E7,IF(B7="retire",J7+K7+L7,0)) -> 146117.97 | N7: =IF(A7>=Inputs!$B$8,0,G7*(1+Inputs!$B$19)+I7-L7) -> 878092.88
A8: =A7+1 -> 35 | B8: =IF(A8<Inputs!$B$20,"work",IF(A8<Inputs!$B$8,"retire","—")) -> work | C8: =IF(B8<>"work",0,IF(A8-Inputs!$B$5<Inputs!$B$13,Inputs!$B$11+(Inputs!$B$12-Inputs!$B$11)*(A8-Inputs!$B$5)/Inputs!$B$13,IF(A8-Inputs!$B$5<Inputs!$B$13+Inputs!$B$14,Inputs!$B$12,Inputs!$B$15))) -> 215000 | D8: =IF(C8<=0,0,VLOOKUP(C8,Inputs!$A$39:$C$48,3,TRUE())+(C8-VLOOKUP(C8,Inputs!$A$39:$C$48,1,TRUE()))*VLOOKUP(C8,Inputs!$A$39:$C$48,2,TRUE())) -> 68882.03 | E8: =C8-D8 -> 146117.97 | F8: =IF(B8="work",E8*Inputs!$B$16,0) -> 40913.032 | G8: =N7 -> 878092.88 | H8: =IF(A8>Inputs!$B$8,0,G8*Inputs!$B$19) -> 61466.501 | I8: =IF(B8="work",F8,0) -> 40913.032 | J8: =IF(AND(A8>=Inputs!$B$23,A8<Inputs!$B$8),Inputs!$B$32,0) -> 0 | K8: =IF(AND(A8>=Inputs!$B$33,A8<Inputs!$B$8),Inputs!$B$35,0) -> 0 | L8: =IF(B8="retire",Summary!$B$11-J8-K8,0) -> 0 | M8: =IF(B8="work",E8,IF(B8="retire",J8+K8+L8,0)) -> 146117.97 | N8: =IF(A8>=Inputs!$B$8,0,G8*(1+Inputs!$B$19)+I8-L8) -> 980472.41
A9: =A8+1 -> 36 | B9: =IF(A9<Inputs!$B$20,"work",IF(A9<Inputs!$B$8,"retire","—")) -> work | C9: =IF(B9<>"work",0,IF(A9-Inputs!$B$5<Inputs!$B$13,Inputs!$B$11+(Inputs!$B$12-Inputs!$B$11)*(A9-Inputs!$B$5)/Inputs!$B$13,IF(A9-Inputs!$B$5<Inputs!$B$13+Inputs!$B$14,Inputs!$B$12,Inputs!$B$15))) -> 215000 | D9: =IF(C9<=0,0,VLOOKUP(C9,Inputs!$A$39:$C$48,3,TRUE())+(C9-VLOOKUP(C9,Inputs!$A$39:$C$48,1,TRUE()))*VLOOKUP(C9,Inputs!$A$39:$C$48,2,TRUE())) -> 68882.03 | E9: =C9-D9 -> 146117.97 | F9: =IF(B9="work",E9*Inputs!$B$16,0) -> 40913.032 | G9: =N8 -> 980472.41 | H9: =IF(A9>Inputs!$B$8,0,G9*Inputs!$B$19) -> 68633.069 | I9: =IF(B9="work",F9,0) -> 40913.032 | J9: =IF(AND(A9>=Inputs!$B$23,A9<Inputs!$B$8),Inputs!$B$32,0) -> 0 | K9: =IF(AND(A9>=Inputs!$B$33,A9<Inputs!$B$8),Inputs!$B$35,0) -> 0 | L9: =IF(B9="retire",Summary!$B$11-J9-K9,0) -> 0 | M9: =IF(B9="work",E9,IF(B9="retire",J9+K9+L9,0)) -> 146117.97 | N9: =IF(A9>=Inputs!$B$8,0,G9*(1+Inputs!$B$19)+I9-L9) -> 1090018.5
A10: =A9+1 -> 37 | B10: =IF(A10<Inputs!$B$20,"work",IF(A10<Inputs!$B$8,"retire","—")) -> work | C10: =IF(B10<>"work",0,IF(A10-Inputs!$B$5<Inputs!$B$13,Inputs!$B$11+(Inputs!$B$12-Inputs!$B$11)*(A10-Inputs!$B$5)/Inputs!$B$13,IF(A10-Inputs!$B$5<Inputs!$B$13+Inputs!$B$14,Inputs!$B$12,Inputs!$B$15))) -> 215000 | D10: =IF(C10<=0,0,VLOOKUP(C10,Inputs!$A$39:$C$48,3,TRUE())+(C10-VLOOKUP(C10,Inputs!$A$39:$C$48,1,TRUE()))*VLOOKUP(C10,Inputs!$A$39:$C$48,2,TRUE())) -> 68882.03 | E10: =C10-D10 -> 146117.97 | F10: =IF(B10="work",E10*Inputs!$B$16,0) -> 40913.032 | G10: =N9 -> 1090018.5 | H10: =IF(A10>Inputs!$B$8,0,G10*Inputs!$B$19) -> 76301.296 | I10: =IF(B10="work",F10,0) -> 40913.032 | J10: =IF(AND(A10>=Inputs!$B$23,A10<Inputs!$B$8),Inputs!$B$32,0) -> 0 | K10: =IF(AND(A10>=Inputs!$B$33,A10<Inputs!$B$8),Inputs!$B$35,0) -> 0 | L10: =IF(B10="retire",Summary!$B$11-J10-K10,0) -> 0 | M10: =IF(B10="work",E10,IF(B10="retire",J10+K10+L10,0)) -> 146117.97 | N10: =IF(A10>=Inputs!$B$8,0,G10*(1+Inputs!$B$19)+I10-L10) -> 1207232.8
A11: =A10+1 -> 38 | B11: =IF(A11<Inputs!$B$20,"work",IF(A11<Inputs!$B$8,"retire","—")) -> work | C11: =IF(B11<>"work",0,IF(A11-Inputs!$B$5<Inputs!$B$13,Inputs!$B$11+(Inputs!$B$12-Inputs!$B$11)*(A11-Inputs!$B$5)/Inputs!$B$13,IF(A11-Inputs!$B$5<Inputs!$B$13+Inputs!$B$14,Inputs!$B$12,Inputs!$B$15))) -> 215000 | D11: =IF(C11<=0,0,VLOOKUP(C11,Inputs!$A$39:$C$48,3,TRUE())+(C11-VLOOKUP(C11,Inputs!$A$39:$C$48,1,TRUE()))*VLOOKUP(C11,Inputs!$A$39:$C$48,2,TRUE())) -> 68882.03 | E11: =C11-D11 -> 146117.97 | F11: =IF(B11="work",E11*Inputs!$B$16,0) -> 40913.032 | G11: =N10 -> 1207232.8 | H11: =IF(A11>Inputs!$B$8,0,G11*Inputs!$B$19) -> 84506.299 | I11: =IF(B11="work",F11,0) -> 40913.032 | J11: =IF(AND(A11>=Inputs!$B$23,A11<Inputs!$B$8),Inputs!$B$32,0) -> 0 | K11: =IF(AND(A11>=Inputs!$B$33,A11<Inputs!$B$8),Inputs!$B$35,0) -> 0 | L11: =IF(B11="retire",Summary!$B$11-J11-K11,0) -> 0 | M11: =IF(B11="work",E11,IF(B11="retire",J11+K11+L11,0)) -> 146117.97 | N11: =IF(A11>=Inputs!$B$8,0,G11*(1+Inputs!$B$19)+I11-L11) -> 1332652.2
A12: =A11+1 -> 39 | B12: =IF(A12<Inputs!$B$20,"work",IF(A12<Inputs!$B$8,"retire","—")) -> work | C12: =IF(B12<>"work",0,IF(A12-Inputs!$B$5<Inputs!$B$13,Inputs!$B$11+(Inputs!$B$12-Inputs!$B$11)*(A12-Inputs!$B$5)/Inputs!$B$13,IF(A12-Inputs!$B$5<Inputs!$B$13+Inputs!$B$14,Inputs!$B$12,Inputs!$B$15))) -> 130000 | D12: =IF(C12<=0,0,VLOOKUP(C12,Inputs!$A$39:$C$48,3,TRUE())+(C12-VLOOKUP(C12,Inputs!$A$39:$C$48,1,TRUE()))*VLOOKUP(C12,Inputs!$A$39:$C$48,2,TRUE())) -> 32431.528 | E12: =C12-D12 -> 97568.472 | F12: =IF(B12="work",E12*Inputs!$B$16,0) -> 27319.172 | G12: =N11 -> 1332652.2 | H12: =IF(A12>Inputs!$B$8,0,G12*Inputs!$B$19) -> 93285.652 | I12: =IF(B12="work",F12,0) -> 27319.172 | J12: =IF(AND(A12>=Inputs!$B$23,A12<Inputs!$B$8),Inputs!$B$32,0) -> 0 | K12: =IF(AND(A12>=Inputs!$B$33,A12<Inputs!$B$8),Inputs!$B$35,0) -> 0 | L12: =IF(B12="retire",Summary!$B$11-J12-K12,0) -> 0 | M12: =IF(B12="work",E12,IF(B12="retire",J12+K12+L12,0)) -> 97568.472 | N12: =IF(A12>=Inputs!$B$8,0,G12*(1+Inputs!$B$19)+I12-L12) -> 1453257
A13: =A12+1 -> 40 | B13: =IF(A13<Inputs!$B$20,"work",IF(A13<Inputs!$B$8,"retire","—")) -> work | C13: =IF(B13<>"work",0,IF(A13-Inputs!$B$5<Inputs!$B$13,Inputs!$B$11+(Inputs!$B$12-Inputs!$B$11)*(A13-Inputs!$B$5)/Inputs!$B$13,IF(A13-Inputs!$B$5<Inputs!$B$13+Inputs!$B$14,Inputs!$B$12,Inputs!$B$15))) -> 130000 | D13: =IF(C13<=0,0,VLOOKUP(C13,Inputs!$A$39:$C$48,3,TRUE())+(C13-VLOOKUP(C13,Inputs!$A$39:$C$48,1,TRUE()))*VLOOKUP(C13,Inputs!$A$39:$C$48,2,TRUE())) -> 32431.528 | E13: =C13-D13 -> 97568.472 | F13: =IF(B13="work",E13*Inputs!$B$16,0) -> 27319.172 | G13: =N12 -> 1453257 | H13: =IF(A13>Inputs!$B$8,0,G13*Inputs!$B$19) -> 101727.99 | I13: =IF(B13="work",F13,0) -> 27319.172 | J13: =IF(AND(A13>=Inputs!$B$23,A13<Inputs!$B$8),Inputs!$B$32,0) -> 0 | K13: =IF(AND(A13>=Inputs!$B$33,A13<Inputs!$B$8),Inputs!$B$35,0) -> 0 | L13: =IF(B13="retire",Summary!$B$11-J13-K13,0) -> 0 | M13: =IF(B13="work",E13,IF(B13="retire",J13+K13+L13,0)) -> 97568.472 | N13: =IF(A13>=Inputs!$B$8,0,G13*(1+Inputs!$B$19)+I13-L13) -> 1582304.2
A14: =A13+1 -> 41 | B14: =IF(A14<Inputs!$B$20,"work",IF(A14<Inputs!$B$8,"retire","—")) -> work | C14: =IF(B14<>"work",0,IF(A14-Inputs!$B$5<Inputs!$B$13,Inputs!$B$11+(Inputs!$B$12-Inputs!$B$11)*(A14-Inputs!$B$5)/Inputs!$B$13,IF(A14-Inputs!$B$5<Inputs!$B$13+Inputs!$B$14,Inputs!$B$12,Inputs!$B$15))) -> 130000 | D14: =IF(C14<=0,0,VLOOKUP(C14,Inputs!$A$39:$C$48,3,TRUE())+(C14-VLOOKUP(C14,Inputs!$A$39:$C$48,1,TRUE()))*VLOOKUP(C14,Inputs!$A$39:$C$48,2,TRUE())) -> 32431.528 | E14: =C14-D14 -> 97568.472 | F14: =IF(B14="work",E14*Inputs!$B$16,0) -> 27319.172 | G14: =N13 -> 1582304.2 | H14: =IF(A14>Inputs!$B$8,0,G14*Inputs!$B$19) -> 110761.29 | I14: =IF(B14="work",F14,0) -> 27319.172 | J14: =IF(AND(A14>=Inputs!$B$23,A14<Inputs!$B$8),Inputs!$B$32,0) -> 0 | K14: =IF(AND(A14>=Inputs!$B$33,A14<Inputs!$B$8),Inputs!$B$35,0) -> 0 | L14: =IF(B14="retire",Summary!$B$11-J14-K14,0) -> 0 | M14: =IF(B14="work",E14,IF(B14="retire",J14+K14+L14,0)) -> 97568.472 | N14: =IF(A14>=Inputs!$B$8,0,G14*(1+Inputs!$B$19)+I14-L14) -> 1720384.6
... A81: =A80+1 -> 108 | B81: =IF(A81<Inputs!$B$20,"work",IF(A81<Inputs!$B$8,"retire","—")) -> — | C81: =IF(B81<>"work",0,IF(A81-Inputs!$B$5<Inputs!$B$13,Inputs!$B$11+(Inputs!$B$12-Inputs!$B$11)*(A81-Inputs!$B$5)/Inputs!$B$13,IF(A81-Inputs!$B$5<Inputs!$B$13+Inputs!$B$14,Inputs!$B$12,Inputs!$B$15))) -> 0 | D81: =IF(C81<=0,0,VLOOKUP(C81,Inputs!$A$39:$C$48,3,TRUE())+(C81-VLOOKUP(C81,Inputs!$A$39:$C$48,1,TRUE()))*VLOOKUP(C81,Inputs!$A$39:$C$48,2,TRUE())) -> 0 | E81: =C81-D81 -> 0 | F81: =IF(B81="work",E81*Inputs!$B$16,0) -> 0 | G81: =N80 -> 0 | H81: =IF(A81>Inputs!$B$8,0,G81*Inputs!$B$19) -> 0 | I81: =IF(B81="work",F81,0) -> 0 | J81: =IF(AND(A81>=Inputs!$B$23,A81<Inputs!$B$8),Inputs!$B$32,0) -> 0 | K81: =IF(AND(A81>=Inputs!$B$33,A81<Inputs!$B$8),Inputs!$B$35,0) -> 0 | L81: =IF(B81="retire",Summary!$B$11-J81-K81,0) -> 0 | M81: =IF(B81="work",E81,IF(B81="retire",J81+K81+L81,0)) -> 0 | N81: =IF(A81>=Inputs!$B$8,0,G81*(1+Inputs!$B$19)+I81-L81) -> 0

Sheet Summary
A1: The headline numbers
A2: All figures in 2026 dollars. Read with the caveats on the Notes tab.
A4: Portfolio at retirement | B4: =INDEX(Projection!G:G,MATCH(Inputs!$B$20,Projection!A:A,0)) -> 6743608.9
A5: Annual retirement income (sustainable, level) | B5: =B11 -> 531912.63
A6: (after estimated OAS clawback)
A8: MATH
A9: Years in retirement | B9: =Inputs!$B$8-Inputs!$B$20 -> 35 | D9: Lifespan minus retirement age.
A10: Annuity factor (retirement period) | B10: =(1-(1+Inputs!$B$19)^-B9)/Inputs!$B$19 -> 12.947672 | D10: PV of $1 per year over retirement at the real return.
A11: Sustainable income (net of clawback) | B11: =B15-B16 -> 531912.63 | D11: What you actually receive each year, in today's dollars.
A12: Present value of CPP (at retirement) | B12: =Inputs!$B$32*((1-(1+Inputs!$B$19)^-MAX(0,Inputs!$B$8-Inputs!$B$23))/Inputs!$B$19)/(1+Inputs!$B$19)^MAX(0,Inputs!$B$23-Inputs!$B$20) -> 180323.25
A13: Present value of OAS (at retirement) | B13: =Inputs!$B$35*((1-(1+Inputs!$B$19)^-MAX(0,Inputs!$B$8-Inputs!$B$33))/Inputs!$B$19)/(1+Inputs!$B$19)^MAX(0,Inputs!$B$33-Inputs!$B$20) -> 79627.274
A14: Total present value (portfolio + CPP + OAS) | B14: =B4+B12+B13 -> 7003559.4
A15: Sustainable income (gross) | B15: =B14/B10 -> 540912.63 | D15: Total PV divided by annuity factor.
A16: OAS clawback estimate | B16: =MIN(Inputs!$B$35, MAX(0, B15-Inputs!$B$26)*0.15) -> 9000 | D16: 15% of income above the OAS threshold.
A18: INCOME BREAKDOWN AT FULL RETIREMENT (CPP + OAS + portfolio)
A19: Source | B19: Annual amount | C19: Begins at age
A20: Portfolio draw (level) | B20: =B15-Inputs!$B$32-Inputs!$B$35 -> 501473.65 | C20: =Inputs!$B$20 -> 60
A21: Canada Pension Plan | B21: =Inputs!$B$32 -> 30438.974 | C21: =Inputs!$B$23 -> 70
A22: Old Age Security | B22: =Inputs!$B$35 -> 9000 | C22: =Inputs!$B$33 -> 65
A23: OAS clawback | B23: =-B16 -> -9000
A24: Net annual income | B24: =B11 -> 531912.63
A26: CPP DETAIL
A27: Years contributing to CPP | B27: =Inputs!$B$29 -> 38
A28: Percentage of max CPP earned | B28: =Inputs!$B$30 -> 0.97435897 | D28: Retire earlier and this drops. 39 contribution years gets 100%.
A29: Boost or cut from claim age | B29: =Inputs!$B$31 -> 1.42 | D29: Claim before 65 cuts; defer past 65 boosts.

Sheet Notes
A1: Method and caveats
A3: METHOD
A4: Income trajectory is linear from current to peak over the 'years until peak' you specify, then flat at peak for 'years held at peak', then steps down to the post-step income for the rest of the career.
A6: Tax uses Ontario 2026 combined federal+provincial marginal brackets. The brackets are on the Inputs tab, editable. Tax for any income X uses VLOOKUP on the cumulative-tax table.
A8: Saving is a fixed share of after-tax income. Portfolio grows at the real return each year (one figure, after inflation), with savings added during work years and a level draw taken during retirement.
A10: CPP is scaled two ways. First by contribution years: 39 years of contributions at the max earnings ceiling gets the full benefit; fewer years prorate it. Second by claim age: claim at 60 cuts to 64% of the 65 amount, claim at 70 boosts to 142%.
A12: OAS depends on Canadian residence, not contributions, so it is not affected by early retirement. It can only start at 65 or later, with up to 36% boost for deferring to 70.
A14: Sustainable income is found by treating CPP and OAS as deferred life annuities, summing their present values with the portfolio at retirement, and dividing by the annuity factor for the retirement period. This gives a level real income that depletes the combined value at lifespan.
A16: OAS clawback is estimated once based on the level income, and netted off the gross. The projection draws portfolio to deliver the net income each year.
A18: CAVEATS
A19: Real returns of 7% are the long-run average for stocks. A balanced portfolio with bonds runs closer to 5%. Adjust the real-return cell on the Inputs tab to test this.
A21: Sequence-of-returns risk is the killer this model hides. A bad first decade after you stop working can wreck a plan that looks healthy on paper. The level annuity assumption smooths over that.
... A27: Tax brackets are an approximation of Ontario 2026. They are inputs you can edit on the Inputs tab if rates change.
